<?xml version="1.0"?><robot name="pepe">
	<link name="0">
		<visual>
			<geometry>
				<cylinder length="0.65" radius="0.325"/>
			</geometry>
		</visual>
		<collision>
			<geometry>
				<cylinder length="0.65" radius="0.325"/>
			</geometry>
		</collision>
		<inertial>
			<mass value="0.21568997062302425"/>
			<inertia ixx="0.013289647669116547" iyy="0.013289647669116547" izz="0.011391126573528467" ixy="0" ixz="0" iyz="0"/>
		</inertial>
	</link>
	<link name="11">
		<visual>
			<geometry>
				<cylinder length="1.04" radius="0.325"/>
			</geometry>
		</visual>
		<collision>
			<geometry>
				<cylinder length="1.04" radius="0.325"/>
			</geometry>
		</collision>
		<inertial>
			<mass value="0.34510395299683877"/>
			<inertia ixx="0.04021827088893784" iyy="0.04021827088893784" izz="0.018225802517645547" ixy="0" ixz="0" iyz="0"/>
		</inertial>
	</link>
	<joint name="11_to_0" type="revolute">
		<parent link="0"/>
		<child link="11"/>
		<axis xyz="0 1 0"/>
		<limit effort="1" upper="3.1415" lower="-3.1415" velocity="1"/>
		<origin rpy="0.0 0.0 0.0" xyz="0.5700000000000001 0.0 0.0"/>
	</joint>
</robot>
