<?xml version="1.0"?><robot name="pepe">
	<link name="0">
		<visual>
			<geometry>
				<cylinder length="0.566096535289482" radius="0.06423227800929465"/>
			</geometry>
		</visual>
		<collision>
			<geometry>
				<cylinder length="0.566096535289482" radius="0.06423227800929465"/>
			</geometry>
		</collision>
		<inertial>
			<mass value="0.007337481491887292"/>
			<inertia ixx="0.03" iyy="0.03" izz="0.03" ixy="0" ixz="0" iyx="0"/>
		</inertial>
	</link>
	<link name="11">
		<visual>
			<geometry>
				<cylinder length="0.6950923040135429" radius="0.05284983803952781"/>
			</geometry>
		</visual>
		<collision>
			<geometry>
				<cylinder length="0.6950923040135429" radius="0.05284983803952781"/>
			</geometry>
		</collision>
		<inertial>
			<mass value="0.006099295493998278"/>
			<inertia ixx="0.03" iyy="0.03" izz="0.03" ixy="0" ixz="0" iyx="0"/>
		</inertial>
	</link>
	<link name="12">
		<visual>
			<geometry>
				<cylinder length="0.6950923040135429" radius="0.05284983803952781"/>
			</geometry>
		</visual>
		<collision>
			<geometry>
				<cylinder length="0.6950923040135429" radius="0.05284983803952781"/>
			</geometry>
		</collision>
		<inertial>
			<mass value="0.006099295493998278"/>
			<inertia ixx="0.03" iyy="0.03" izz="0.03" ixy="0" ixz="0" iyx="0"/>
		</inertial>
	</link>
	<link name="13">
		<visual>
			<geometry>
				<cylinder length="0.6950923040135429" radius="0.05284983803952781"/>
			</geometry>
		</visual>
		<collision>
			<geometry>
				<cylinder length="0.6950923040135429" radius="0.05284983803952781"/>
			</geometry>
		</collision>
		<inertial>
			<mass value="0.006099295493998278"/>
			<inertia ixx="0.03" iyy="0.03" izz="0.03" ixy="0" ixz="0" iyx="0"/>
		</inertial>
	</link>
	<link name="24">
		<visual>
			<geometry>
				<cylinder length="0.4149074603367672" radius="0.4379212166612972"/>
			</geometry>
		</visual>
		<collision>
			<geometry>
				<cylinder length="0.4149074603367672" radius="0.4379212166612972"/>
			</geometry>
		</collision>
		<inertial>
			<mass value="0.2499729928016025"/>
			<inertia ixx="0.03" iyy="0.03" izz="0.03" ixy="0" ixz="0" iyx="0"/>
		</inertial>
	</link>
	<joint name="11_to_0" type="revolute">
		<parent link="0"/>
		<child link="11"/>
		<axis xyz="0 1 0"/>
		<limit effort="1" upper="-3.1415" lower="3.1415" velocity="1"/>
		<origin rpy="8.067978117775592 2.694689802316899 3.251427043631656" xyz="0.41244013730074225 0.17398692755749967 0.8104611031487328"/>
	</joint>
	<joint name="12_to_0" type="revolute">
		<parent link="0"/>
		<child link="12"/>
		<axis xyz="0 1 0"/>
		<limit effort="1" upper="-3.1415" lower="3.1415" velocity="1"/>
		<origin rpy="12.101967176663388 2.694689802316899 3.251427043631656" xyz="0.41244013730074225 0.17398692755749967 0.8104611031487328"/>
	</joint>
	<joint name="13_to_0" type="revolute">
		<parent link="0"/>
		<child link="13"/>
		<axis xyz="0 1 0"/>
		<limit effort="1" upper="-3.1415" lower="3.1415" velocity="1"/>
		<origin rpy="16.135956235551184 2.694689802316899 3.251427043631656" xyz="0.41244013730074225 0.17398692755749967 0.8104611031487328"/>
	</joint>
	<joint name="24_to_0" type="revolute">
		<parent link="0"/>
		<child link="24"/>
		<axis xyz="0 0 1"/>
		<limit effort="1" upper="-3.1415" lower="3.1415" velocity="1"/>
		<origin rpy="11.372530246323223 2.2227633803798414 4.830161811812665" xyz="0.7623505641157408 0.19244925293935772 0.9462391548407004"/>
	</joint>
</robot>
