<?xml version="1.0"?><robot name="pepe">
	<link name="0">
		<visual>
			<geometry>
				<cylinder length="0.9936574974004084" radius="0.14785592289824545"/>
			</geometry>
		</visual>
		<collision>
			<geometry>
				<cylinder length="0.9936574974004084" radius="0.14785592289824545"/>
			</geometry>
		</collision>
		<inertial>
			<mass value="0.06824393164631085"/>
			<inertia ixx="0.03" iyy="0.03" izz="0.03" ixy="0" ixz="0" iyx="0"/>
		</inertial>
	</link>
	<link name="11">
		<visual>
			<geometry>
				<cylinder length="0.7440710708578562" radius="0.13437824354579808"/>
			</geometry>
		</visual>
		<collision>
			<geometry>
				<cylinder length="0.7440710708578562" radius="0.13437824354579808"/>
			</geometry>
		</collision>
		<inertial>
			<mass value="0.04221066679325304"/>
			<inertia ixx="0.03" iyy="0.03" izz="0.03" ixy="0" ixz="0" iyx="0"/>
		</inertial>
	</link>
	<link name="22">
		<visual>
			<geometry>
				<cylinder length="0.35049340519577266" radius="0.7398712534331663"/>
			</geometry>
		</visual>
		<collision>
			<geometry>
				<cylinder length="0.35049340519577266" radius="0.7398712534331663"/>
			</geometry>
		</collision>
		<inertial>
			<mass value="0.6027566785865304"/>
			<inertia ixx="0.03" iyy="0.03" izz="0.03" ixy="0" ixz="0" iyx="0"/>
		</inertial>
	</link>
	<link name="23">
		<visual>
			<geometry>
				<cylinder length="0.35049340519577266" radius="0.7398712534331663"/>
			</geometry>
		</visual>
		<collision>
			<geometry>
				<cylinder length="0.35049340519577266" radius="0.7398712534331663"/>
			</geometry>
		</collision>
		<inertial>
			<mass value="0.6027566785865304"/>
			<inertia ixx="0.03" iyy="0.03" izz="0.03" ixy="0" ixz="0" iyx="0"/>
		</inertial>
	</link>
	<link name="14">
		<visual>
			<geometry>
				<cylinder length="0.7440710708578562" radius="0.13437824354579808"/>
			</geometry>
		</visual>
		<collision>
			<geometry>
				<cylinder length="0.7440710708578562" radius="0.13437824354579808"/>
			</geometry>
		</collision>
		<inertial>
			<mass value="0.04221066679325304"/>
			<inertia ixx="0.03" iyy="0.03" izz="0.03" ixy="0" ixz="0" iyx="0"/>
		</inertial>
	</link>
	<link name="25">
		<visual>
			<geometry>
				<cylinder length="0.35049340519577266" radius="0.7398712534331663"/>
			</geometry>
		</visual>
		<collision>
			<geometry>
				<cylinder length="0.35049340519577266" radius="0.7398712534331663"/>
			</geometry>
		</collision>
		<inertial>
			<mass value="0.6027566785865304"/>
			<inertia ixx="0.03" iyy="0.03" izz="0.03" ixy="0" ixz="0" iyx="0"/>
		</inertial>
	</link>
	<link name="26">
		<visual>
			<geometry>
				<cylinder length="0.35049340519577266" radius="0.7398712534331663"/>
			</geometry>
		</visual>
		<collision>
			<geometry>
				<cylinder length="0.35049340519577266" radius="0.7398712534331663"/>
			</geometry>
		</collision>
		<inertial>
			<mass value="0.6027566785865304"/>
			<inertia ixx="0.03" iyy="0.03" izz="0.03" ixy="0" ixz="0" iyx="0"/>
		</inertial>
	</link>
	<link name="17">
		<visual>
			<geometry>
				<cylinder length="0.7440710708578562" radius="0.13437824354579808"/>
			</geometry>
		</visual>
		<collision>
			<geometry>
				<cylinder length="0.7440710708578562" radius="0.13437824354579808"/>
			</geometry>
		</collision>
		<inertial>
			<mass value="0.04221066679325304"/>
			<inertia ixx="0.03" iyy="0.03" izz="0.03" ixy="0" ixz="0" iyx="0"/>
		</inertial>
	</link>
	<link name="28">
		<visual>
			<geometry>
				<cylinder length="0.35049340519577266" radius="0.7398712534331663"/>
			</geometry>
		</visual>
		<collision>
			<geometry>
				<cylinder length="0.35049340519577266" radius="0.7398712534331663"/>
			</geometry>
		</collision>
		<inertial>
			<mass value="0.6027566785865304"/>
			<inertia ixx="0.03" iyy="0.03" izz="0.03" ixy="0" ixz="0" iyx="0"/>
		</inertial>
	</link>
	<link name="29">
		<visual>
			<geometry>
				<cylinder length="0.35049340519577266" radius="0.7398712534331663"/>
			</geometry>
		</visual>
		<collision>
			<geometry>
				<cylinder length="0.35049340519577266" radius="0.7398712534331663"/>
			</geometry>
		</collision>
		<inertial>
			<mass value="0.6027566785865304"/>
			<inertia ixx="0.03" iyy="0.03" izz="0.03" ixy="0" ixz="0" iyx="0"/>
		</inertial>
	</link>
	<joint name="11_to_0" type="revolute">
		<parent link="0"/>
		<child link="11"/>
		<axis xyz="1 0 0"/>
		<limit effort="1" upper="-3.1415" lower="3.1415" velocity="1"/>
		<origin rpy="6.9301001175068775 4.544657722797063 3.5321751726918023" xyz="0.2968792383886708 0.6257359090449465 0.6350248467932161"/>
	</joint>
	<joint name="22_to_11" type="revolute">
		<parent link="11"/>
		<child link="22"/>
		<axis xyz="0 0 1"/>
		<limit effort="1" upper="-3.1415" lower="3.1415" velocity="1"/>
		<origin rpy="7.7432642297688465 0.5725819966998213 3.894563894619473" xyz="0.5699394173942979 0.5887691123488297 0.18950314772707033"/>
	</joint>
	<joint name="23_to_11" type="revolute">
		<parent link="11"/>
		<child link="23"/>
		<axis xyz="0 0 1"/>
		<limit effort="1" upper="-3.1415" lower="3.1415" velocity="1"/>
		<origin rpy="11.61489634465327 0.5725819966998213 3.894563894619473" xyz="0.5699394173942979 0.5887691123488297 0.18950314772707033"/>
	</joint>
	<joint name="14_to_0" type="revolute">
		<parent link="0"/>
		<child link="14"/>
		<axis xyz="1 0 0"/>
		<limit effort="1" upper="-3.1415" lower="3.1415" velocity="1"/>
		<origin rpy="10.395150176260316 4.544657722797063 3.5321751726918023" xyz="0.2968792383886708 0.6257359090449465 0.6350248467932161"/>
	</joint>
	<joint name="25_to_14" type="revolute">
		<parent link="14"/>
		<child link="25"/>
		<axis xyz="0 0 1"/>
		<limit effort="1" upper="-3.1415" lower="3.1415" velocity="1"/>
		<origin rpy="7.7432642297688465 0.5725819966998213 3.894563894619473" xyz="0.5699394173942979 0.5887691123488297 0.18950314772707033"/>
	</joint>
	<joint name="26_to_14" type="revolute">
		<parent link="14"/>
		<child link="26"/>
		<axis xyz="0 0 1"/>
		<limit effort="1" upper="-3.1415" lower="3.1415" velocity="1"/>
		<origin rpy="11.61489634465327 0.5725819966998213 3.894563894619473" xyz="0.5699394173942979 0.5887691123488297 0.18950314772707033"/>
	</joint>
	<joint name="17_to_0" type="revolute">
		<parent link="0"/>
		<child link="17"/>
		<axis xyz="1 0 0"/>
		<limit effort="1" upper="-3.1415" lower="3.1415" velocity="1"/>
		<origin rpy="13.860200235013755 4.544657722797063 3.5321751726918023" xyz="0.2968792383886708 0.6257359090449465 0.6350248467932161"/>
	</joint>
	<joint name="28_to_17" type="revolute">
		<parent link="17"/>
		<child link="28"/>
		<axis xyz="0 0 1"/>
		<limit effort="1" upper="-3.1415" lower="3.1415" velocity="1"/>
		<origin rpy="7.7432642297688465 0.5725819966998213 3.894563894619473" xyz="0.5699394173942979 0.5887691123488297 0.18950314772707033"/>
	</joint>
	<joint name="29_to_17" type="revolute">
		<parent link="17"/>
		<child link="29"/>
		<axis xyz="0 0 1"/>
		<limit effort="1" upper="-3.1415" lower="3.1415" velocity="1"/>
		<origin rpy="11.61489634465327 0.5725819966998213 3.894563894619473" xyz="0.5699394173942979 0.5887691123488297 0.18950314772707033"/>
	</joint>
</robot>
